Workbook
Name CODECHECK: Cn_code!$A$1:$B$14
Name Pricelist: Price_list!$A$1:$B$13
Name Slicer_Email_Status: #N/A

Sheet Analysis Dashboard
A1: Email Marketing Attribution & ROI AnalysisA1:Z30
A3: CORE METRICS | D3: I. Foundational & Operational Performance | L3: II. Pricing And Market Strategy | U3: III. Marketing Attribution And ROI
A5: TOTAL SUBMISSION | B5: 4000 | D5: Revenue Concentration | H5: Operational Peak | L5: Discount Profitibility | P5: Unique Filmmaker Penetration By Country | U5: Attribution Breakdown | Y5: Golden Hour (Email Conversion)
A6: TOTAL REVENUE | B6: 191625
A7: AVG. FINAL FEE | B7: =B6/B5 -> 47.90625 | D7: Country | E7: Revenue | F7: Revenue(%) | H7: Submission Hour | I7: Revenue | J7: Total Submission | L7: Discount % | M7: Avg. Final Fee | N7: Total Submission | P7: Country | Q7: Unique Filmmaker Count | R7: Total Submission | S7: Repetition Rate | U7: Email Attribution Status | V7: Total Submission | W7: Revenue | Y7: Email Hour | Z7: Total Submission
A8: ATTRIBUTION% | B8: 0.683 | D8: United States | E8: 37623 | F8: 0.19633659 | H8: 11 | I8: 23851 | J8: 498 | L8: 0 | M8: 59.357907 | N8: 841 | P8: United States | Q8: 699 | R8: 786 | S8: =GETPIVOTDATA("[Measures].[Count of Submitter_ID]",$P$7,"[Table1].[Country_Name]","[Table1].[Country_Name].&[United States]")/GETPIVOTDATA("[Measures].[Distinct Count of Filmmaker_ID]",$P$7,"[Table1].[Country_Name]","[Table1].[Country_Name].&[United States]") -> 1.1244635 | U8: Email Opened | V8: 2038 | W8: 98017 | Y8: 15 | Z8: 71
D9: India | E9: 26767 | F9: 0.13968428 | H9: 16 | I9: 21998 | J9: 454 | L9: 0.1 | M9: 54.771429 | N9: 455 | P9: India | Q9: 514 | R9: 561 | S9: =GETPIVOTDATA("[Measures].[Count of Submitter_ID]",$P$7,"[Table1].[Country_Name]","[Table1].[Country_Name].&[India]")/GETPIVOTDATA("[Measures].[Distinct Count of Filmmaker_ID]",$P$7,"[Table1].[Country_Name]","[Table1].[Country_Name].&[India]") -> 1.0914397 | U9: Email Clicked | V9: 695 | W9: 33038 | Y9: 10 | Z9: 65
D10: United Kingdom | E10: 21221 | F10: 0.11074234 | H10: 17 | I10: 21841 | J10: 447 | L10: 0.2 | M10: 48 | N10: 934 | P10: United Kingdom | Q10: 396 | R10: 433 | S10: =GETPIVOTDATA("[Measures].[Count of Submitter_ID]",$P$7,"[Table1].[Country_Name]","[Table1].[Country_Name].&[United Kingdom]")/GETPIVOTDATA("[Measures].[Distinct Count of Filmmaker_ID]",$P$7,"[Table1].[Country_Name]","[Table1].[Country_Name].&[United Kingdom]") -> 1.0934343 | U10: Organic Baseline | V10: 1267 | W10: 60570 | Y10: 11 | Z10: 61
D11: Germany | E11: 19366 | F11: 0.10106197 | H11: 12 | I11: 21766 | J11: 455 | L11: 0.3 | M11: 42.031437 | N11: 1336 | P11: Germany | Q11: 377 | R11: 403 | S11: =GETPIVOTDATA("[Measures].[Count of Submitter_ID]",$P$7,"[Table1].[Country_Name]","[Table1].[Country_Name].&[Germany]")/GETPIVOTDATA("[Measures].[Distinct Count of Filmmaker_ID]",$P$7,"[Table1].[Country_Name]","[Table1].[Country_Name].&[Germany]") -> 1.0689655 | U11: Grand Total | V11: 4000 | W11: 191625 | Y11: 14 | Z11: 60
D12: Others | E12: 18969 | F12: 0.098990215 | H12: 13 | I12: 21187 | J12: 445 | L12: 0.4 | M12: 36.400922 | N12: 434 | P12: Others | Q12: 364 | R12: 397 | S12: =GETPIVOTDATA("[Measures].[Count of Submitter_ID]",$P$7,"[Table1].[Country_Name]","[Table1].[Country_Name].&[Others]")/GETPIVOTDATA("[Measures].[Distinct Count of Filmmaker_ID]",$P$7,"[Table1].[Country_Name]","[Table1].[Country_Name].&[Others]") -> 1.0906593 | Y12: 19 | Z12: 58
D13: South Korea | E13: 10312 | F13: 0.053813438 | H13: 14 | I13: 20824 | J13: 438 | P13: South Korea | Q13: 211 | R13: 214 | S13: =GETPIVOTDATA("[Measures].[Count of Submitter_ID]",$P$7,"[Table1].[Country_Name]","[Table1].[Country_Name].&[South Korea]")/GETPIVOTDATA("[Measures].[Distinct Count of Filmmaker_ID]",$P$7,"[Table1].[Country_Name]","[Table1].[Country_Name].&[South Korea]") -> 1.014218 | U13: While the campaign is highly influential, the Viewed volume (2,058) is nearly 3x higher than the Clicked volume (695). This gap signals conversion friction. Customise a stronger Call-to-Action (CTA) language and optimize the email creative to drive higher direct click-through rates | Y13: 16 | Z13: 51
D14: France | E14: 9716 | F14: 0.050703196 | H14: 15 | I14: 20425 | J14: 432 | L14: 0% discount yields the highest avg final fee($59.36). Eliminite 0.4 discounts as it erodes margin. Promote mid tier discounts (0.1,0.2,0.3) to find a balance between volume-profit. | P14: Australia | Q14: 202 | R14: 205 | S14: =GETPIVOTDATA("[Measures].[Count of Submitter_ID]",$P$7,"[Table1].[Country_Name]","[Table1].[Country_Name].&[Australia]")/GETPIVOTDATA("[Measures].[Distinct Count of Filmmaker_ID]",$P$7,"[Table1].[Country_Name]","[Table1].[Country_Name].&[Australia]") -> 1.0148515 | Y14: 17 | Z14: 49
D15: Nigeria | E15: 9667 | F15: 0.050447489 | H15: 9 | I15: 20408 | J15: 434 | P15: Canada | Q15: 200 | R15: 201 | S15: =GETPIVOTDATA("[Measures].[Count of Submitter_ID]",$P$7,"[Table1].[Country_Name]","[Table1].[Country_Name].&[Canada]")/GETPIVOTDATA("[Measures].[Distinct Count of Filmmaker_ID]",$P$7,"[Table1].[Country_Name]","[Table1].[Country_Name].&[Canada]") -> 1.005 | Y15: 12 | Z15: 49
D16: Canada | E16: 9568 | F16: 0.049930855 | H16: 10 | I16: 19325 | J16: 397 | P16: Nigeria | Q16: 199 | R16: 206 | S16: =GETPIVOTDATA("[Measures].[Count of Submitter_ID]",$P$7,"[Table1].[Country_Name]","[Table1].[Country_Name].&[Nigeria]")/GETPIVOTDATA("[Measures].[Distinct Count of Filmmaker_ID]",$P$7,"[Table1].[Country_Name]","[Table1].[Country_Name].&[Nigeria]") -> 1.0351759 | Y16: 18 | Z16: 49
D17: Mexico | E17: 9529 | F17: 0.049727332 | H17: Grand Total | I17: 191625 | J17: 4000 | P17: Mexico | Q17: 195 | R17: 201 | S17: =GETPIVOTDATA("[Measures].[Count of Submitter_ID]",$P$7,"[Table1].[Country_Name]","[Table1].[Country_Name].&[Mexico]")/GETPIVOTDATA("[Measures].[Distinct Count of Filmmaker_ID]",$P$7,"[Table1].[Country_Name]","[Table1].[Country_Name].&[Mexico]") -> 1.0307692 | Y17: 7 | Z17: 49
D18: Australia | E18: 9527 | F18: 0.049716895 | P18: Brazil | Q18: 194 | R18: 194 | S18: =GETPIVOTDATA("[Measures].[Count of Submitter_ID]",$P$7,"[Table1].[Country_Name]","[Table1].[Country_Name].&[Brazil]")/GETPIVOTDATA("[Measures].[Distinct Count of Filmmaker_ID]",$P$7,"[Table1].[Country_Name]","[Table1].[Country_Name].&[Brazil]") -> 1 | Y18: 13 | Z18: 48
D19: Brazil | E19: 9360 | F19: 0.048845401 | H19: Peak revenue hours are 11 AM,16 PM,17 PM,12 PM (IST). Maximise customer support and server monitoring to prevent service disruption during 11-17 operational window. | P19: France | Q19: 191 | R19: 199 | S19: =GETPIVOTDATA("[Measures].[Count of Submitter_ID]",$P$7,"[Table1].[Country_Name]","[Table1].[Country_Name].&[France]")/GETPIVOTDATA("[Measures].[Distinct Count of Filmmaker_ID]",$P$7,"[Table1].[Country_Name]","[Table1].[Country_Name].&[France]") -> 1.0418848 | Y19: 9 | Z19: 44
D20: Grand Total | E20: 191625 | F20: 1 | P20: Grand Total | Q20: 2278 | R20: 4000 | Y20: 8 | Z20: 41
Y21: Grand Total | Z21: 695
D22: The US, India, and UK drive 44.0% of total revenue. Action: Prioritize strategic growth in the next tier of high-value countries (e.g., Germany, South Korea) to diversify revenue sources. | P22: A Repetition Rate of approx 1.0 across all markets signals low customer loyalty, meaning the current business model is highly reliant on new customer acquisition. Immediately optimize the customer funnel with a clear focus on retention and loyalty incentives to build long-term customer value.
Y23: The two strongest conversion hours are 15 and 10 (3 PM and 10 AM). Schedule all future email sends to align with the 16:00-17:00 time window to capture maximum immediate intent.

Sheet Submission_data
A1: Submitter_ID | B1: Filmmaker_ID | C1: Category | D1: Country_Code | E1: Country_Name | F1: Base_Fee | G1: Discount_Percentage | H1: Final_Fee | I1: Submission_Date | J1: Submission_Day | K1: Submission_Time | L1: Submission_Hour | M1: Email_Status | N1: Email_Hour
A2: SUB_1 | B2: ID_3632 | C2: Short Film | D2: IN | E2: =VLOOKUP(D2,CODECHECK,2,FALSE) -> India | F2: =VLOOKUP(C2,Pricelist,2,FALSE) -> 70 | G2: 0.4 | H2: =F2-(G2*F2) -> 42 | I2: 45855 | J2: =TEXT(I2,"ddd") -> Thu | K2: 0.56458333 | L2: =HOUR(K2) -> 13 | M2: =_xlfn.XLOOKUP(B2,Email_Data!A:A,Email_Data!C:C,"Organic",0) -> 0 | N2: =_xlfn.XLOOKUP(Table1[[#This Row],[Filmmaker_ID]],Email_Data!$A:$A,Email_Data!$G:$G,"Not Found") -> 16
A3: SUB_2 | B3: ID_3463 | C3: Short Script | D3: NG | E3: =VLOOKUP(D3,CODECHECK,2,FALSE) -> Nigeria | F3: =VLOOKUP(C3,Pricelist,2,FALSE) -> 70 | G3: 0.2 | H3: =F3-(G3*F3) -> 56 | I3: 45842 | J3: =TEXT(I3,"ddd") -> Fri | K3: 0.66875 | L3: =HOUR(K3) -> 16 | M3: =_xlfn.XLOOKUP(B3,Email_Data!A:A,Email_Data!C:C,"Organic",0) -> 0 | N3: =_xlfn.XLOOKUP(Table1[[#This Row],[Filmmaker_ID]],Email_Data!$A:$A,Email_Data!$G:$G,"Not Found") -> 12
A4: SUB_3 | B4: ID_2351 | C4: Feature Script | D4: KR | E4: =VLOOKUP(D4,CODECHECK,2,FALSE) -> South Korea | F4: =VLOOKUP(C4,Pricelist,2,FALSE) -> 80 | G4: 0 | H4: =F4-(G4*F4) -> 80 | I4: 45893 | J4: =TEXT(I4,"ddd") -> Sun | K4: 0.52430556 | L4: =HOUR(K4) -> 12 | M4: =_xlfn.XLOOKUP(B4,Email_Data!A:A,Email_Data!C:C,"Organic",0) -> 0 | N4: =_xlfn.XLOOKUP(Table1[[#This Row],[Filmmaker_ID]],Email_Data!$A:$A,Email_Data!$G:$G,"Not Found") -> 9
A5: SUB_4 | B5: ID_2164 | C5: Best Actor | D5: US | E5: =VLOOKUP(D5,CODECHECK,2,FALSE) -> United States | F5: =VLOOKUP(C5,Pricelist,2,FALSE) -> 50 | G5: 0.2 | H5: =F5-(G5*F5) -> 40 | I5: 45884 | J5: =TEXT(I5,"ddd") -> Fri | K5: 0.66736111 | L5: =HOUR(K5) -> 16 | M5: =_xlfn.XLOOKUP(B5,Email_Data!A:A,Email_Data!C:C,"Organic",0) -> 0 | N5: =_xlfn.XLOOKUP(Table1[[#This Row],[Filmmaker_ID]],Email_Data!$A:$A,Email_Data!$G:$G,"Not Found") -> 19
A6: SUB_5 | B6: ID_2708 | C6: Short Script | D6: IN | E6: =VLOOKUP(D6,CODECHECK,2,FALSE) -> India | F6: =VLOOKUP(C6,Pricelist,2,FALSE) -> 70 | G6: 0.2 | H6: =F6-(G6*F6) -> 56 | I6: 45848 | J6: =TEXT(I6,"ddd") -> Thu | K6: 0.43958333 | L6: =HOUR(K6) -> 10 | M6: =_xlfn.XLOOKUP(B6,Email_Data!A:A,Email_Data!C:C,"Organic",0) -> 0 | N6: =_xlfn.XLOOKUP(Table1[[#This Row],[Filmmaker_ID]],Email_Data!$A:$A,Email_Data!$G:$G,"Not Found") -> 14
A7: SUB_6 | B7: ID_1944 | C7: Best Cinematography | D7: UK | E7: =VLOOKUP(D7,CODECHECK,2,FALSE) -> United Kingdom | F7: =VLOOKUP(C7,Pricelist,2,FALSE) -> 50 | G7: 0.3 | H7: =F7-(G7*F7) -> 35 | I7: 45854 | J7: =TEXT(I7,"ddd") -> Wed | K7: 0.49861111 | L7: =HOUR(K7) -> 11 | M7: =_xlfn.XLOOKUP(B7,Email_Data!A:A,Email_Data!C:C,"Organic",0) -> 0 | N7: =_xlfn.XLOOKUP(Table1[[#This Row],[Filmmaker_ID]],Email_Data!$A:$A,Email_Data!$G:$G,"Not Found") -> 7
A8: SUB_7 | B8: ID_2170 | C8: Short Film | D8: OTH | E8: =VLOOKUP(D8,CODECHECK,2,FALSE) -> Others | F8: =VLOOKUP(C8,Pricelist,2,FALSE) -> 70 | G8: 0.3 | H8: =F8-(G8*F8) -> 49 | I8: 45851 | J8: =TEXT(I8,"ddd") -> Sun | K8: 0.49930556 | L8: =HOUR(K8) -> 11 | M8: =_xlfn.XLOOKUP(B8,Email_Data!A:A,Email_Data!C:C,"Organic",0) -> Organic | N8: =_xlfn.XLOOKUP(Table1[[#This Row],[Filmmaker_ID]],Email_Data!$A:$A,Email_Data!$G:$G,"Not Found") -> Not Found
A9: SUB_8 | B9: ID_1425 | C9: Best Sound Design | D9: BR | E9: =VLOOKUP(D9,CODECHECK,2,FALSE) -> Brazil | F9: =VLOOKUP(C9,Pricelist,2,FALSE) -> 50 | G9: 0 | H9: =F9-(G9*F9) -> 50 | I9: 45847 | J9: =TEXT(I9,"ddd") -> Wed | K9: 0.41736111 | L9: =HOUR(K9) -> 10 | M9: =_xlfn.XLOOKUP(B9,Email_Data!A:A,Email_Data!C:C,"Organic",0) -> 0 | N9: =_xlfn.XLOOKUP(Table1[[#This Row],[Filmmaker_ID]],Email_Data!$A:$A,Email_Data!$G:$G,"Not Found") -> 8
A10: SUB_9 | B10: ID_3893 | C10: Best Sound Design | D10: OTH | E10: =VLOOKUP(D10,CODECHECK,2,FALSE) -> Others | F10: =VLOOKUP(C10,Pricelist,2,FALSE) -> 50 | G10: 0.3 | H10: =F10-(G10*F10) -> 35 | I10: 45861 | J10: =TEXT(I10,"ddd") -> Wed | K10: 0.38541667 | L10: =HOUR(K10) -> 9 | M10: =_xlfn.XLOOKUP(B10,Email_Data!A:A,Email_Data!C:C,"Organic",0) -> 0 | N10: =_xlfn.XLOOKUP(Table1[[#This Row],[Filmmaker_ID]],Email_Data!$A:$A,Email_Data!$G:$G,"Not Found") -> 8
A11: SUB_10 | B11: ID_1222 | C11: Best Director | D11: MX | E11: =VLOOKUP(D11,CODECHECK,2,FALSE) -> Mexico | F11: =VLOOKUP(C11,Pricelist,2,FALSE) -> 50 | G11: 0.2 | H11: =F11-(G11*F11) -> 40 | I11: 45853 | J11: =TEXT(I11,"ddd") -> Tue | K11: 0.74861111 | L11: =HOUR(K11) -> 17 | M11: =_xlfn.XLOOKUP(B11,Email_Data!A:A,Email_Data!C:C,"Organic",0) -> 0 | N11: =_xlfn.XLOOKUP(Table1[[#This Row],[Filmmaker_ID]],Email_Data!$A:$A,Email_Data!$G:$G,"Not Found") -> 10
A12: SUB_11 | B12: ID_3463 | C12: Documentary | D12: DE | E12: =VLOOKUP(D12,CODECHECK,2,FALSE) -> Germany | F12: =VLOOKUP(C12,Pricelist,2,FALSE) -> 70 | G12: 0.4 | H12: =F12-(G12*F12) -> 42 | I12: 45868 | J12: =TEXT(I12,"ddd") -> Wed | K12: 0.47222222 | L12: =HOUR(K12) -> 11 | M12: =_xlfn.XLOOKUP(B12,Email_Data!A:A,Email_Data!C:C,"Organic",0) -> 0 | N12: =_xlfn.XLOOKUP(Table1[[#This Row],[Filmmaker_ID]],Email_Data!$A:$A,Email_Data!$G:$G,"Not Found") -> 12
A13: SUB_12 | B13: ID_3060 | C13: Best Cinematography | D13: BR | E13: =VLOOKUP(D13,CODECHECK,2,FALSE) -> Brazil | F13: =VLOOKUP(C13,Pricelist,2,FALSE) -> 50 | G13: 0 | H13: =F13-(G13*F13) -> 50 | I13: 45856 | J13: =TEXT(I13,"ddd") -> Fri | K13: 0.53541667 | L13: =HOUR(K13) -> 12 | M13: =_xlfn.XLOOKUP(B13,Email_Data!A:A,Email_Data!C:C,"Organic",0) -> 1 | N13: =_xlfn.XLOOKUP(Table1[[#This Row],[Filmmaker_ID]],Email_Data!$A:$A,Email_Data!$G:$G,"Not Found") -> 18
... A4001: SUB_4000 | B4001: ID_2129 | C4001: Best Producer | D4001: NG | E4001: =VLOOKUP(D4001,CODECHECK,2,FALSE) -> Nigeria | F4001: =VLOOKUP(C4001,Pricelist,2,FALSE) -> 50 | G4001: 0 | H4001: =F4001-(G4001*F4001) -> 50 | I4001: 45877 | J4001: =TEXT(I4001,"ddd") -> Fri | K4001: 0.48263889 | L4001: =HOUR(K4001) -> 11 | M4001: =_xlfn.XLOOKUP(B4001,Email_Data!A:A,Email_Data!C:C,"Organic",0) -> Organic | N4001: =_xlfn.XLOOKUP(Table1[[#This Row],[Filmmaker_ID]],Email_Data!$A:$A,Email_Data!$G:$G,"Not Found") -> Not Found

Sheet Email_Data
A1: Filmmaker_ID | B1: Email_Open | C1: Email_Click | D1: Date_Sent | E1: Day_Sent | F1: Time_Sent | G1: Email_Hour
A2: ID_1052 | B2: 1 | C2: 0 | D2: 45885 | E2: Sat | F2: 0.64861111 | G2: =HOUR(F2) -> 15
A3: ID_1500 | B3: 1 | C3: 1 | D3: 45862 | E3: Thu | F3: 0.30138889 | G3: =HOUR(F3) -> 7
A4: ID_3451 | B4: 1 | C4: 0 | D4: 45896 | E4: Wed | F4: 0.60972222 | G4: =HOUR(F4) -> 14
A5: ID_2293 | B5: 0 | C5: 0 | D5: 45885 | E5: Sat | F5: 0.62847222 | G5: =HOUR(F5) -> 15
A6: ID_1092 | B6: 0 | C6: 0 | D6: 45878 | E6: Sat | F6: 0.31736111 | G6: =HOUR(F6) -> 7
A7: ID_2728 | B7: 0 | C7: 0 | D7: 45841 | E7: Thu | F7: 0.62361111 | G7: =HOUR(F7) -> 14
A8: ID_1413 | B8: 0 | C8: 0 | D8: 45877 | E8: Fri | F8: 0.59027778 | G8: =HOUR(F8) -> 14
A9: ID_1342 | B9: 1 | C9: 1 | D9: 45858 | E9: Sun | F9: 0.40972222 | G9: =HOUR(F9) -> 9
A10: ID_1410 | B10: 1 | C10: 0 | D10: 45844 | E10: Sun | F10: 0.76388889 | G10: =HOUR(F10) -> 18
A11: ID_3997 | B11: 1 | C11: 1 | D11: 45875 | E11: Wed | F11: 0.33611111 | G11: =HOUR(F11) -> 8
A12: ID_1243 | B12: 1 | C12: 0 | D12: 45896 | E12: Wed | F12: 0.31875 | G12: =HOUR(F12) -> 7
A13: ID_3976 | B13: 1 | C13: 0 | D13: 45873 | E13: Mon | F13: 0.40694444 | G13: =HOUR(F13) -> 9
... A4001: ID_1483 | B4001: 0 | C4001: 0 | D4001: 45879 | E4001: Sun | F4001: 0.82777778 | G4001: =HOUR(F4001) -> 19

Sheet Cn_code
A1: CODE | B1: COUNTRY
A2: Code | B2: Name
A3: US | B3: United States
A4: IN | B4: India
A5: UK | B5: United Kingdom
A6: DE | B6: Germany
A7: CA | B7: Canada
A8: AU | B8: Australia
A9: BR | B9: Brazil
A10: FR | B10: France
A11: MX | B11: Mexico
A12: KR | B12: South Korea
... A14: OTH | B14: Others

Sheet Price_list
A1: Category | B1: Price
A2: Short Film | B2: 70
A3: Short Script | B3: 70
A4: Feature Script | B4: 80
A5: Best Actor | B5: 50
A6: Best Cinematography | B6: 50
A7: Best Sound Design | B7: 50
A8: Best Director | B8: 50
A9: Documentary | B9: 70
A10: Best Producer | B10: 50
A11: Best Actress | B11: 50
A12: Best Editing | B12: 50
A13: Feature Film | B13: 80

Sheet visualisation_data
A1: Submitter_ID | B1: Filmmaker_ID | C1: Category | D1: Country_Name | E1: Discount_Percentage | F1: Final_Fee | G1: Submission_Day | H1: Submission_Hour | I1: Email_Status | J1: Email_Hour
A2: SUB_1 | B2: ID_3632 | C2: Short Film | D2: India | E2: 0.4 | F2: 42 | G2: Thu | H2: 13 | I2: 0 | J2: 16
A3: SUB_2 | B3: ID_3463 | C3: Short Script | D3: Nigeria | E3: 0.2 | F3: 56 | G3: Fri | H3: 16 | I3: 0 | J3: 12
A4: SUB_3 | B4: ID_2351 | C4: Feature Script | D4: South Korea | E4: 0 | F4: 80 | G4: Sun | H4: 12 | I4: 0 | J4: 9
A5: SUB_4 | B5: ID_2164 | C5: Best Actor | D5: United States | E5: 0.2 | F5: 40 | G5: Fri | H5: 16 | I5: 0 | J5: 19
A6: SUB_5 | B6: ID_2708 | C6: Short Script | D6: India | E6: 0.2 | F6: 56 | G6: Thu | H6: 10 | I6: 0 | J6: 14
A7: SUB_6 | B7: ID_1944 | C7: Best Cinematography | D7: United Kingdom | E7: 0.3 | F7: 35 | G7: Wed | H7: 11 | I7: 0 | J7: 7
A8: SUB_7 | B8: ID_2170 | C8: Short Film | D8: Others | E8: 0.3 | F8: 49 | G8: Sun | H8: 11 | I8: Organic | J8: Not Found
A9: SUB_8 | B9: ID_1425 | C9: Best Sound Design | D9: Brazil | E9: 0 | F9: 50 | G9: Wed | H9: 10 | I9: 0 | J9: 8
A10: SUB_9 | B10: ID_3893 | C10: Best Sound Design | D10: Others | E10: 0.3 | F10: 35 | G10: Wed | H10: 9 | I10: 0 | J10: 8
A11: SUB_10 | B11: ID_1222 | C11: Best Director | D11: Mexico | E11: 0.2 | F11: 40 | G11: Tue | H11: 17 | I11: 0 | J11: 10
A12: SUB_11 | B12: ID_3463 | C12: Documentary | D12: Germany | E12: 0.4 | F12: 42 | G12: Wed | H12: 11 | I12: 0 | J12: 12
A13: SUB_12 | B13: ID_3060 | C13: Best Cinematography | D13: Brazil | E13: 0 | F13: 50 | G13: Fri | H13: 12 | I13: 1 | J13: 18
A14: SUB_13 | B14: ID_3810 | C14: Best Producer | D14: India | E14: 0.2 | F14: 40 | G14: Sat | H14: 15 | I14: Organic | J14: Not Found
A15: SUB_14 | B15: ID_3412 | C15: Best Actress | D15: France | E15: 0.2 | F15: 40 | G15: Tue | H15: 11 | I15: 0 | J15: 7
A16: SUB_15 | B16: ID_4097 | C16: Best Actress | D16: South Korea | E16: 0.2 | F16: 40 | G16: Thu | H16: 12 | I16: Organic | J16: Not Found
A17: SUB_16 | B17: ID_2170 | C17: Best Editing | D17: United States | E17: 0.3 | F17: 35 | G17: Sat | H17: 10 | I17: Organic | J17: Not Found
A18: SUB_17 | B18: ID_2523 | C18: Best Producer | D18: Australia | E18: 0.2 | F18: 40 | G18: Wed | H18: 13 | I18: 1 | J18: 12
A19: SUB_18 | B19: ID_3919 | C19: Best Sound Design | D19: Australia | E19: 0.2 | F19: 40 | G19: Mon | H19: 10 | I19: Organic | J19: Not Found
A20: SUB_19 | B20: ID_1193 | C20: Best Director | D20: Others | E20: 0.3 | F20: 35 | G20: Fri | H20: 12 | I20: 0 | J20: 17
A21: SUB_20 | B21: ID_4080 | C21: Best Actor | D21: Mexico | E21: 0.2 | F21: 40 | G21: Fri | H21: 12 | I21: Organic | J21: Not Found
A22: SUB_21 | B22: ID_2994 | C22: Best Actor | D22: India | E22: 0.2 | F22: 40 | G22: Thu | H22: 11 | I22: 1 | J22: 12
A23: SUB_22 | B23: ID_2518 | C23: Short Script | D23: United Kingdom | E23: 0.2 | F23: 56 | G23: Wed | H23: 16 | I23: Organic | J23: Not Found
A24: SUB_23 | B24: ID_2243 | C24: Best Director | D24: Others | E24: 0.4 | F24: 30 | G24: Sun | H24: 9 | I24: 1 | J24: 18
A25: SUB_24 | B25: ID_3733 | C25: Feature Script | D25: Australia | E25: 0.1 | F25: 72 | G25: Wed | H25: 9 | I25: 1 | J25: 12
A26: SUB_25 | B26: ID_1767 | C26: Best Cinematography | D26: Nigeria | E26: 0.2 | F26: 40 | G26: Wed | H26: 12 | I26: 0 | J26: 7
A27: SUB_26 | B27: ID_3004 | C27: Best Director | D27: Brazil | E27: 0.3 | F27: 35 | G27: Wed | H27: 9 | I27: 0 | J27: 11
A28: SUB_27 | B28: ID_2168 | C28: Best Sound Design | D28: United States | E28: 0.3 | F28: 35 | G28: Tue | H28: 11 | I28: 0 | J28: 10
A29: SUB_28 | B29: ID_2725 | C29: Best Actress | D29: Others | E29: 0.2 | F29: 40 | G29: Tue | H29: 12 | I29: 0 | J29: 8
A30: SUB_29 | B30: ID_3608 | C30: Feature Film | D30: India | E30: 0 | F30: 80 | G30: Wed | H30: 16 | I30: Organic | J30: Not Found
A31: SUB_30 | B31: ID_2524 | C31: Feature Film | D31: United States | E31: 0.2 | F31: 64 | G31: Sun | H31: 17 | I31: 1 | J31: 19
A32: SUB_31 | B32: ID_1171 | C32: Short Script | D32: South Korea | E32: 0.1 | F32: 63 | G32: Sat | H32: 12 | I32: 0 | J32: 18
A33: SUB_32 | B33: ID_1559 | C33: Short Film | D33: India | E33: 0.3 | F33: 49 | G33: Sat | H33: 11 | I33: 0 | J33: 9
A34: SUB_33 | B34: ID_2529 | C34: Feature Film | D34: Nigeria | E34: 0.2 | F34: 64 | G34: Mon | H34: 17 | I34: Organic | J34: Not Found
A35: SUB_34 | B35: ID_1614 | C35: Best Actress | D35: Canada | E35: 0.3 | F35: 35 | G35: Sun | H35: 15 | I35: 1 | J35: 15
A36: SUB_35 | B36: ID_4180 | C36: Short Film | D36: Nigeria | E36: 0.3 | F36: 49 | G36: Tue | H36: 14 | I36: Organic | J36: Not Found
A37: SUB_36 | B37: ID_3498 | C37: Best Director | D37: United States | E37: 0 | F37: 50 | G37: Mon | H37: 17 | I37: 0 | J37: 19
A38: SUB_37 | B38: ID_3078 | C38: Best Cinematography | D38: United States | E38: 0 | F38: 50 | G38: Mon | H38: 16 | I38: 1 | J38: 16
A39: SUB_38 | B39: ID_3674 | C39: Best Editing | D39: France | E39: 0 | F39: 50 | G39: Sun | H39: 16 | I39: 0 | J39: 17
A40: SUB_39 | B40: ID_3809 | C40: Best Actress | D40: United States | E40: 0.3 | F40: 35 | G40: Thu | H40: 10 | I40: 0 | J40: 14
...
